<?xml version="1.0"?>

<robot xmlns:xacro="http://www.ros.org/wiki/xacro" 
	name="infantry_xacro">


  <link
    name="base_link">
    <inertial>
      <origin
        xyz="-0.025782 -8.2911E-05 0.025311"
        rpy="0 0 0" />
      <mass
        value="7.625" />
      <inertia
        ixx="0.10311"
        ixy="-9.0391E-05"
        ixz="0.0071078"
        iyy="0.24575"
        iyz="2.1083E-05"
        izz="0.32438" />
    </inertial>
    <visual>
      <origin
        xyz="0 0 0"
        rpy="0 0 0" />
      <geometry>
        <mesh
          filename="package://infantryb/meshes/base_link.STL" />
      </geometry>
      <material
        name="">
        <color
          rgba="0 0 0 1" />
      </material>
    </visual>
    <collision>
      <origin
        xyz="0 0 0"
        rpy="0 0 0" />
      <geometry>
        <mesh
          filename="package://infantryb/meshes/base_link.STL" />
      </geometry>
    </collision>
  </link>
  <link
    name="fl_wheel_Link">
    <inertial>
      <origin
        xyz="-5.232E-06 0.014616 -9.0427E-06"
        rpy="0 0 0" />
      <mass
        value="0.86078" />
      <inertia
        ixx="0.0015361"
        ixy="1.6456E-06"
        ixz="-2.0131E-06"
        iyy="0.002844"
        iyz="-9.5351E-07"
        izz="0.0015337" />
    </inertial>
    <visual>
      <origin
        xyz="0 0 0"
        rpy="0 0 0" />
      <geometry>
        <mesh
          filename="package://infantryb/meshes/fl_wheel_Link.STL" />
      </geometry>
      <material
        name="">
        <color
          rgba="1 0 0 1" />
      </material>
    </visual>
    <collision>
      <origin
        xyz="0 0 0"
        rpy="0 0 0" />
      <geometry>
        <mesh
          filename="package://infantryb/meshes/fl_wheel_Link.STL" />
      </geometry>
    </collision>
  </link>
  <joint
    name="base_link_to_fl_wheel_joint"
    type="continuous">
    <origin
      xyz="-0.21206 -0.2003 0.0022"
      rpy="4.8881E-16 -3.6891E-17 -3.1416" />
    <parent
      link="base_link" />
    <child
      link="fl_wheel_Link" />
    <axis
      xyz="0 1 0" />
  </joint>
  <link
    name="fr_wheel_Link">
    <inertial>
      <origin
        xyz="0.00010086 -0.014551 4.8285E-05"
        rpy="0 0 0" />
      <mass
        value="0.86078" />
      <inertia
        ixx="0.0015355"
        ixy="4.8831E-07"
        ixz="1.8067E-06"
        iyy="0.002844"
        iyz="9.4618E-08"
        izz="0.0015338" />
    </inertial>
    <visual>
      <origin
        xyz="0 0 0"
        rpy="0 0 0" />
      <geometry>
        <mesh
          filename="package://infantryb/meshes/fr_wheel_Link.STL" />
      </geometry>
      <material
        name="">
        <color
          rgba="0.79216 0.81961 0.93333 1" />
      </material>
    </visual>
    <collision>
      <origin
        xyz="0 0 0"
        rpy="0 0 0" />
      <geometry>
        <mesh
          filename="package://infantryb/meshes/fr_wheel_Link.STL" />
      </geometry>
    </collision>
  </link>
  <joint
    name="base_link_to_fr_wheel_joint"
    type="continuous">
    <origin
      xyz="-0.21206 0.2009 0.0022"
      rpy="6.9321E-17 -3.6891E-17 -3.1416" />
    <parent
      link="base_link" />
    <child
      link="fr_wheel_Link" />
    <axis
      xyz="0 -1 0" />
  </joint>
  <link
    name="br_wheel_Link">
    <inertial>
      <origin
        xyz="-5.2323E-06 -0.014549 -9.0423E-06"
        rpy="0 0 0" />
      <mass
        value="0.86078" />
      <inertia
        ixx="0.0015361"
        ixy="1.6481E-06"
        ixz="-2.0131E-06"
        iyy="0.002844"
        iyz="-9.4912E-07"
        izz="0.0015338" />
    </inertial>
    <visual>
      <origin
        xyz="0 0 0"
        rpy="0 0 0" />
      <geometry>
        <mesh
          filename="package://infantryb/meshes/br_wheel_Link.STL" />
      </geometry>
      <material
        name="">
        <color
          rgba="0.79216 0.81961 0.93333 1" />
      </material>
    </visual>
    <collision>
      <origin
        xyz="0 0 0"
        rpy="0 0 0" />
      <geometry>
        <mesh
          filename="package://infantryb/meshes/br_wheel_Link.STL" />
      </geometry>
    </collision>
  </link>
  <joint
    name="base_link_to_br_wheel_joint"
    type="continuous">
    <origin
      xyz="0.21194 0.2003 0.0022"
      rpy="5.7896E-17 1.5832E-16 3.1416" />
    <parent
      link="base_link" />
    <child
      link="br_wheel_Link" />
    <axis
      xyz="0 1 0" />
  </joint>
  <link
    name="bl_wheel_Link">
    <inertial>
      <origin
        xyz="0.00010086 0.014592 4.8286E-05"
        rpy="0 0 0" />
      <mass
        value="0.86078" />
      <inertia
        ixx="0.0015355"
        ixy="5.3543E-07"
        ixz="1.8067E-06"
        iyy="0.002844"
        iyz="1.1717E-07"
        izz="0.0015337" />
    </inertial>
    <visual>
      <origin
        xyz="0 0 0"
        rpy="0 0 0" />
      <geometry>
        <mesh
          filename="package://infantryb/meshes/bl_wheel_Link.STL" />
      </geometry>
      <material
        name="">
        <color
          rgba="0.75294 0.75294 0.75294 1" />
      </material>
    </visual>
    <collision>
      <origin
        xyz="0 0 0"
        rpy="0 0 0" />
      <geometry>
        <mesh
          filename="package://infantryb/meshes/bl_wheel_Link.STL" />
      </geometry>
    </collision>
  </link>
  <joint
    name="base_link_to_bl_wheel_joint"
    type="continuous">
    <origin
      xyz="0.21194 -0.2009 0.0022"
      rpy="4.8881E-16 -3.6891E-17 -3.1416" />
    <parent
      link="base_link" />
    <child
      link="bl_wheel_Link" />
    <axis
      xyz="0 -1 0" />
  </joint>
  <link
    name="yaw_Link">
    <inertial>
      <origin
        xyz="7.9767E-06 0.024936 0.059798"
        rpy="0 0 0" />
      <mass
        value="0.98307" />
      <inertia
        ixx="0.0072228"
        ixy="1.8624E-07"
        ixz="5.1373E-07"
        iyy="0.0035103"
        iyz="-0.0016193"
        izz="0.00443" />
    </inertial>
    <visual>
      <origin
        xyz="0 0 0"
        rpy="0 0 0" />
      <geometry>
        <mesh
          filename="package://infantryb/meshes/yaw_Link.STL" />
      </geometry>
      <material
        name="">
        <color
          rgba="0.89412 0.91373 0.92941 1" />
      </material>
    </visual>
    <collision>
      <origin
        xyz="0 0 0"
        rpy="0 0 0" />
      <geometry>
        <mesh
          filename="package://infantryb/meshes/yaw_Link.STL" />
      </geometry>
    </collision>
  </link>
  <joint
    name="base_link_to_yaw_joint"
    type="revolute">
    <origin
      xyz="-0.017561 0 0.1342"
      rpy="4.8881E-16 -3.6891E-17 -3.1416" />
    <parent
      link="base_link" />
    <child
      link="yaw_Link" />
    <axis
      xyz="0 0 1" />
    <limit
      lower="-1.57"
      upper="1.57"
      effort="1000"
      velocity="100" />
  </joint>
  <link
    name="pitch_Link">
    <inertial>
      <origin
        xyz="-0.0024244 0.00051587 -0.011372"
        rpy="0 0 0" />
      <mass
        value="0.68228" />
      <inertia
        ixx="0.0019856"
        ixy="5.1373E-05"
        ixz="0.00087772"
        iyy="0.0042744"
        iyz="-2.4468E-05"
        izz="0.0037072" />
    </inertial>
    <visual>
      <origin
        xyz="0 0 0"
        rpy="0 0 0" />
      <geometry>
        <mesh
          filename="package://infantryb/meshes/pitch_Link.STL" />
      </geometry>
      <material
        name="">
        <color
          rgba="1 1 1 1" />
      </material>
    </visual>
    <collision>
      <origin
        xyz="0 0 0"
        rpy="0 0 0" />
      <geometry>
        <mesh
          filename="package://infantryb/meshes/pitch_Link.STL" />
      </geometry>
    </collision>
  </link>
  <joint
    name="base_link_to_pitch_joint"
    type="revolute">
    <origin
      xyz="0 0 0.125"
      rpy="-1.3809E-15 8.0654E-17 6.6834E-14" />
    <parent
      link="yaw_Link" />
    <child
      link="pitch_Link" />
    <axis
      xyz="0 1 0" />
    <limit
      lower="-0.35"
      upper="0.35"
      effort="1000"
      velocity="100" />
  </joint>
  <link
    name="camera_Link">
    <inertial>
      <origin
        xyz="0.0060861 1.0269E-17 7.6833E-05"
        rpy="0 0 0" />
      <mass
        value="0.01627" />
      <inertia
        ixx="3.55E-06"
        ixy="2.3732E-22"
        ixz="1.3726E-09"
        iyy="2.0801E-06"
        iyz="6.7678E-23"
        izz="2.0554E-06" />
    </inertial>
    <visual>
      <origin
        xyz="0 0 0"
        rpy="0 0 0" />
      <geometry>
        <mesh
          filename="package://infantryb/meshes/camera_Link.STL" />
      </geometry>
      <material
        name="">
        <color
          rgba="0.75294 0.75294 0.75294 1" />
      </material>
    </visual>
    <collision>
      <origin
        xyz="0 0 0"
        rpy="0 0 0" />
      <geometry>
        <mesh
          filename="package://infantryb/meshes/camera_Link.STL" />
      </geometry>
    </collision>
  </link>
  <joint
    name="pitch_link_to_camera_wheel_joint"
    type="fixed">
    <origin
      xyz="0.041 0 0.049"
      rpy="1.3809E-15 -8.0654E-17 -6.6834E-14" />
    <parent
      link="pitch_Link" />
    <child
      link="camera_Link" />
    <axis
      xyz="0 0 0" />
  </joint>
  <link
    name="laser_Link">
    <inertial>
      <origin
        xyz="-0.00019454 1.2441E-18 0.027108"
        rpy="0 0 0" />
      <mass
        value="0.12185" />
      <inertia
        ixx="6.3159E-05"
        ixy="-9.0976E-22"
        ixz="-4.4573E-07"
        iyy="6.3776E-05"
        iyz="-1.8492E-21"
        izz="4.2072E-05" />
    </inertial>
    <visual>
      <origin
        xyz="0 0 0"
        rpy="0 0 0" />
      <geometry>
        <mesh
          filename="package://infantryb/meshes/laser_Link.STL" />
      </geometry>
      <material
        name="">
        <color
          rgba="0.75294 0.75294 0.75294 1" />
      </material>
    </visual>
    <collision>
      <origin
        xyz="0 0 0"
        rpy="0 0 0" />
      <geometry>
        <mesh
          filename="package://infantryb/meshes/laser_Link.STL" />
      </geometry>
    </collision>
  </link>
  <joint
    name="base_link_to_laser_joint"
    type="fixed">
    <origin
      xyz="-0.21456 0 0.0842"
      rpy="4.8881E-16 -3.6891E-17 -3.1416" />
    <parent
      link="base_link" />
    <child
      link="laser_Link" />
    <axis
      xyz="0 0 0" />
  </joint>
  <link
    name="led_Link">
    <inertial>
      <origin
        xyz="-0.27282 -0.063339 0.010089"
        rpy="0 0 0" />
      <mass
        value="0.028183" />
      <inertia
        ixx="0.00037048"
        ixy="7.803E-06"
        ixz="9.4378E-05"
        iyy="0.0011379"
        iyz="-1.4266E-06"
        izz="0.0014674" />
    </inertial>
    <visual>
      <origin
        xyz="0 0 0"
        rpy="0 0 0" />
      <geometry>
        <mesh
          filename="package://infantryb/meshes/led_Link.STL" />
      </geometry>
      <material
        name="">
        <color
          rgba="1 0 0 1" />
      </material>
    </visual>
    <collision>
      <origin
        xyz="0 0 0"
        rpy="0 0 0" />
      <geometry>
        <mesh
          filename="package://infantryb/meshes/led_Link.STL" />
      </geometry>
    </collision>
  </link>
  <joint
    name="base_link_to_led_joint"
    type="fixed">
    <origin
      xyz="-0.28244 -0.063339 0.061918"
      rpy="1.0523E-16 2.5064E-17 3.1416" />
    <parent
      link="base_link" />
    <child
      link="led_Link" />
    <axis
      xyz="0 0 0" />
  </joint>
</robot>
